# 예외상황과 예외처리의 이해
* 프로그램 실행 중에 발생하는 문제의 상황을 예외상황이라고함
* 예시
    * 나이를 입력하라고 했는데, 0보다 작은 값이 입력되는경우
    * 나눗셈을 위해서 두개의 숫자를 입력 받았는데, 제수로 0이 입력되는 경우
    * 주민등록번호 13자리만 입력하라고 명시되었지만 중간에 -가 삽입됨
* 예외는 문법적 오류가 아닌, 프로그램 논리에 맞지 안흔 오류를 뜻함

## if문을 이용한 예외처리
* if 문을 이용해서 예외를 발견하고 처리하면, 예외처리 부분과 일반적인 프로그램의 흐름을 쉽게 구부할 수 없음
* if문은 일반적인 프로그램의 논리를 구혀하는데 주로 사용
* C++은 별도의 예외처리 메커니즘을 제공
```c++
if main(void)
{
    int num1,num2;
    cout<<"두 개의 숫자 입력: ";
    cin>>num1>>num2;
    if(num2==0) // 예외발견
    {// 예외처리
        cout<<"제수는 0이 될 수 없습니다."<<endl;
        cout<<"프로그램을 다시 실행하세요."<<endl;
    }
    else
    {
        cout<<"나눗셈의 몫: "<<num1/num2<<endl;
        cout<<"나눗셈의 몫: "<<num1%num2<<endl;
    }
    return 0;
}

// 두 개의 숫자 입력 : 7 0
// 제수는 0이 될 수 없습니다.
// 프로그램을 다시 실행하세요.
```
  
# C++의 예외처리 메커니즘
## try, catch, throw 
* try는 예외 발생에 대한 검사 버무이를 지정하는데 사용
* catch 블록은 try블록에서 발생한 예외를 처리하는 영역으로 반환형 없는 함수와 같음
* throw는 예외의 발생을 알리는 역할을 한다.
* try~catch는 하나의 문장이므로 그사이에 다른 문장이 삽입될 수 없다.
```c++
try
{
    if(예외 발생)
        throw expn;
}
catch(type expn)
{
    // 예외의 처리 
}
```
### 예외 메커니즘 적용
* 예외가 발생으로 try블록내에서 throw절이 실행되면 try의 나머지 부분은 실행되지 않음 => 이후에 등장하는 catch 블록을 실행
* 예외가 발생하지 않으면 catch 블록은 실행되지 않고 넘어감
```c++
int main(void)
{
    int num1, num2;
    cout <<"두개의 숫자 입력: ";
    cin>>num1>>num2;
    try
    {
        if(num2==0)
            throw num2;
        cout<<"나눗셈의 몫: "<<num1/num2<<endl;
        cout<<"나눗셈의 몫: "<<num1%num2<<endl;
    }
    catch(int expn)
    {
         cout<<"제수는 " <<expn<<"이 될 수 없습니다."<<endl;
        cout<<"프로그램을 다시 실행하세요."<<endl;
    }
    cout<<"end of main"<<endl;
    return 0;
}
// 실행1
// 두 개의 숫자 입력 : 9 2
// 나눗셈의 몫 : 4
// 나눗세믜 나머지 : 1
// end of main

// 실행2
// 두 개의 숫자 입력 : 7 0
// 제수는 0이 될 수 없습니다.
// 프로그램을 다시 실행하세요.
// end of main
```
* try 블록은 예외와 연관된 부분을 모두 같이 묶어주어야 함

# Stack Unwinding(스택풀기)
* 예외가 처리되지 않으면 예외가 발생한 함수를 호출한 영역으로 예외 데이터가 전달
```c++
int main(void)
{
    try
    {
        Divide(num1,num2);
        cout<<" 나눗셈을 마쳤습니다."<<endl;
    }
    catch(int expn)
    {

    }
    return 0;
}
void Divide(int num1, int num2)
{
    if(num2==0)
        throw num2;
}// 함수내에 throw는 있지만 아래에 catch를 정의하지 않기 때문에 예외처리는 main의 catch함수로 전달
```
* main 함수에서조차 예외를 처리하지 안으면, terminate함수(프로그램을 종료시키는 함수)가 호출되면서 프로그램 종료

* 자료형이 일치하지 않아도 예외데이터는 전달가능
* try블록은 한개이지만 catch는 블록을 다르게 지정가능
```c++
try
{
    cout<<str1<<" + "<<str2<<" = "<<StoI(str1)+StoI(str2)<<endl;
    break;
}
catch(char ch)
{
    cout<<"문자 "<<ch << "가 입력되었습니다."<<endl;
    cout <<"재입력 진행합니다."<<endl<<endl;
}
catch(int expn)
{
    if(expn==0)
        cout<<"0으로 시작하는 숫자는 입력 불가"<<endl;
    else
        cout<<"비정상적으로 입력이 이루어졌습니다."<<endl;
    
    cout<<"재입력 진행합니다."<<endl;
}
```

## 전달되는 예외 명시
* 함수 내에서 예외상황의 발생으로 인해서 int형 예외 데이터와 char형 예외 데이터가 전달될 수 있음을 명시한 선언

```c++
int ThrowFunc(int num) throw (int,char)
{} // int,char이외의 예외 데이터가 전달되면, terminate 함수의 호출로 인해서 프로그램이 종료
int SimpleFunc(void) throw()
{}// 어떠한 예외가 발생해도 프로그램은 종료된다는 뜻, 어떠한 예외상황도 발생하지 않는다는 의미
```

# 예외상황을 표현하는 예외 클래스의 설계
* 예외 객체 : 예외 발생을 알리는데 사용되는 객체
* 예외 클래스 : 예외 객체의 생성을 위해 정의된 클래스
* 객체를 이용해서 예외상황을 알리면 예외가 발생한 원인에 대한 정보를 보다 자세히 담을 수 있음
* 하나의 예외클래스가 다수의 예외상황처리가 가능해짐
```c++
class DepositException
{
    private:
        int reqDep; // 요청 입금액
    public:
        DepositException(int money) : reqDep(money){}
        void ShowExceptionReason(){
            cout <<"[예외 메시지 : ]" << reqDep<<"는 입금불가]"<<endl;
        }
}
class WithdrawException
{
    private:
        int balance // 잔고
    public:
       WithdrawException(int money) : balance(money){}
        void ShowExceptionReason(){
            cout <<"[예외 메시지 : 잔액]" << balance<<", 잔액부족]"<<endl;
        }
}
```
## 예외클래스 기반의 예외처리
```c++
class Account
{
    private:
        char accNum[50]; // 계좌 번호
        int balance; //잔고
    public:
        Account(char * acc, int money) : balance(money){
            strcpy(accNum, acc);
        }
        void Deposit(int money) throw (DepositException){
            if(money<0){
                DepositException expn(money);
                throw expn;
            }
            balance +=money;
        }
        void Withdraw(int money) throw (WithdrawException)
        {
            if (money>balance)
                throw WithdrawException(balance);
            balance-=money;
        }
        void ShowMyMoney()
        {
            cout<<"잔고: "<<balance<<endl<<endl;
        }
};
int main(void)
{
    Account myAcc("56789-827120",5000);

    try
    {
        myAcc.Deposit(2000);
        myAcc.Deposit(-300);
    }
    catch(DepositException &expn)
    {
        expn.ShowExceptionReason();
    }
    myAcc.ShowMyMoney();
    try
    {
        myAcc.Withdraw(3500);
        myAcc.Withdraw(4500);
    }
    catch(WithdrawException &expn)// 예외객체는 복사가 필요가 없으므로 참조만 함
    {
        expn.showExceptionReason();
    }
    myAcc.ShowMyMoney();
    retrun 0;
}
```
## 예외의 전달시 주의사항
* 맨위에 있는 catch블록부터 시작해서 아래로 적절한 catch블록을 찾아 내오기 때문에 순서 지정이 중요함
```c++
class AAA
{
    public:
        void ShowYou() {cout<<"AAA exception!"<<endl;}
};
class BBB : public AAA
{
    public:
        void ShowYou() {cout<<"BBB exception!"<<endl;}
};
class CCC : public BBB
{
    public:
        void ShowYou() {cout<<"CCC exception!"<<endl;}
};
try
{
    ExceptionGeneartor(3);
    ExceptionGeneartor(2);
    ExceptionGeneartor(1);
}
catch(AAA& expn)
{
    cout <<"catch(AAA& expn)"<<endl;
    expn.ShowYou();
}
catch(BBB& expn)
{
    cout <<"catch(AAA& expn)"<<endl;
    expn.ShowYou();
}
catch(CCC& expn)
{
    cout <<"catch(AAA& expn)"<<endl;
    expn.ShowYou();
}

//위의 구조에서 B는 A를 상속하고 C는 B를 상속하고 있기때문에 
//첫번째 catch절에서 모두 예외처리가 되기 때문에 catch절을 아래처럼 바꿔야함
catch(CCC& expn)
{
    cout <<"catch(AAA& expn)"<<endl;
    expn.ShowYou();
}
catch(BBB& expn)
{
    cout <<"catch(AAA& expn)"<<endl;
    expn.ShowYou();
}
catch(AAA& expn)
{
    cout <<"catch(AAA& expn)"<<endl;
    expn.ShowYou();
}
```
# 예외처리 특성들
## new 연산자에 의해서 전달되는 예외
* bad_alloc과 같이 프로그래머가 정의하지 않아도 발생하는 예외가 있음
* 대표적인 예시로 형변환 시 발생하는 bad_cast 예외
```c++
int main(void)
{
    int num=0;
    try
    {
        while(1)
        {
            num++;
            cout<<num<<"번째 할당 시도"<<endl;
            new int[10000][10000];
        }
    }
    catch(bad_alloc &bad)
    {
        cout<<bad.what()<<endl;
        cout<<"더 이상 할당 불가!"<<endl;
    }
    return 0;
}
// 1번째 할당 시도
// 2번째 할당 시도
// 3번째 할당 시도
// 4번째 할당 시도
// 5번째 할당 시도
// bad allocation
// 더이상 할당 불가!
```
## 모든 예외를 처리하는 catch 블록
* 발생한 예외와 관련해서 그 어떠한 정보도 전달받을 수 없고, 전달된 예외의 종류도 구분이 불가능 함.
```c++
try
{

}
catch(...) //...은 전달되는 모든 예외를 다 받아주겠다는 선언
{

}
```

## 예외 던지기
* catch 블록에 전달된 예외를 다시 던져서 둘 이상의 catch 블록에서도 처리 가능하도록 만들어줌

```c++
void Divide(int num1, int num2)
{
    try
    {
        if(num2==0)
            throw 0;
        cout<<"몫: "<<num1/num2<<endl;
        cout<<"나머지: "<<num1%num2<<endl; 
    }
    catch(int expn)
    {
        cout<<"first catch"<<endl;
        throw; // 예외를 다시 던짐
    }
}
int main(void)
{
    try
    {
        Divide(9,2);
        Divide(4,0);
    }
    catch(int expn) // Divide 함수에서 처리된 예외가 다시 던져지면서 바깥쪽 main함수에서 한번더 처리
    {
        cout<<"second catch"<<endl;
    }
    return 0;
}
/*
몫 : 4
나머지:1
first catch
second catch
*/
```
```c++

```
```c++

```
```c++

```
```c++

```
```c++

```
```c++

```
```c++

```